[2022-01-26 00:34:43,201] {taskinstance.py:1032} INFO - Dependencies all met for <TaskInstance: user_processing.creating_table scheduled__2021-11-26T00:00:00+00:00 [queued]>
[2022-01-26 00:34:43,213] {taskinstance.py:1032} INFO - Dependencies all met for <TaskInstance: user_processing.creating_table scheduled__2021-11-26T00:00:00+00:00 [queued]>
[2022-01-26 00:34:43,213] {taskinstance.py:1238} INFO - 
--------------------------------------------------------------------------------
[2022-01-26 00:34:43,213] {taskinstance.py:1239} INFO - Starting attempt 1 of 1
[2022-01-26 00:34:43,213] {taskinstance.py:1240} INFO - 
--------------------------------------------------------------------------------
[2022-01-26 00:34:43,225] {taskinstance.py:1259} INFO - Executing <Task(SqliteOperator): creating_table> on 2021-11-26 00:00:00+00:00
[2022-01-26 00:34:43,230] {standard_task_runner.py:52} INFO - Started process 152815 to run task
[2022-01-26 00:34:43,235] {standard_task_runner.py:76} INFO - Running: ['airflow', 'tasks', 'run', 'user_processing', 'creating_table', 'scheduled__2021-11-26T00:00:00+00:00', '--job-id', '469', '--raw', '--subdir', 'DAGS_FOLDER/user_processing.py', '--cfg-path', '/tmp/tmpwolxamal', '--error-file', '/tmp/tmp1gakz2t5']
[2022-01-26 00:34:43,236] {standard_task_runner.py:77} INFO - Job 469: Subtask creating_table
[2022-01-26 00:34:43,301] {logging_mixin.py:109} INFO - Running <TaskInstance: user_processing.creating_table scheduled__2021-11-26T00:00:00+00:00 [running]> on host uiliam-Vostro-15-3515
[2022-01-26 00:34:43,361] {taskinstance.py:1424} INFO - Exporting the following env vars:
AIRFLOW_CTX_DAG_OWNER=airflow
AIRFLOW_CTX_DAG_ID=user_processing
AIRFLOW_CTX_TASK_ID=creating_table
AIRFLOW_CTX_EXECUTION_DATE=2021-11-26T00:00:00+00:00
AIRFLOW_CTX_DAG_RUN_ID=scheduled__2021-11-26T00:00:00+00:00
[2022-01-26 00:34:43,361] {sqlite.py:61} INFO - Executing: 
            CREATE TABLE IF NOT EXISTS users (
            first_name TEXT NOT NULL,
            lastname TEXT NOT NULL,
            country TEXT NOT NULL,
            username TEXT NOT NULL,
            password TEXT NOT NULL,
            email TEXT NOT NULL PRIMARY KEY
            );
            
[2022-01-26 00:34:43,391] {taskinstance.py:1700} ERROR - Task failed with exception
Traceback (most recent call last):
  File "/home/uiliam/sandbox/lib/python3.9/site-packages/airflow/models/taskinstance.py", line 1329, in _run_raw_task
    self._execute_task_with_callbacks(context)
  File "/home/uiliam/sandbox/lib/python3.9/site-packages/airflow/models/taskinstance.py", line 1455, in _execute_task_with_callbacks
    result = self._execute_task(context, self.task)
  File "/home/uiliam/sandbox/lib/python3.9/site-packages/airflow/models/taskinstance.py", line 1511, in _execute_task
    result = execute_callable(context=context)
  File "/home/uiliam/sandbox/lib/python3.9/site-packages/airflow/providers/sqlite/operators/sqlite.py", line 63, in execute
    hook.run(self.sql, parameters=self.parameters)
  File "/home/uiliam/sandbox/lib/python3.9/site-packages/airflow/hooks/dbapi.py", line 198, in run
    with closing(self.get_conn()) as conn:
  File "/home/uiliam/sandbox/lib/python3.9/site-packages/airflow/providers/sqlite/hooks/sqlite.py", line 35, in get_conn
    airflow_conn = self.get_connection(conn_id)
  File "/home/uiliam/sandbox/lib/python3.9/site-packages/airflow/hooks/base.py", line 68, in get_connection
    conn = Connection.get_connection_from_secrets(conn_id)
  File "/home/uiliam/sandbox/lib/python3.9/site-packages/airflow/models/connection.py", line 410, in get_connection_from_secrets
    raise AirflowNotFoundException(f"The conn_id `{conn_id}` isn't defined")
airflow.exceptions.AirflowNotFoundException: The conn_id `db_sqlite` isn't defined
[2022-01-26 00:34:43,401] {taskinstance.py:1267} INFO - Marking task as FAILED. dag_id=user_processing, task_id=creating_table, execution_date=20211126T000000, start_date=20220126T033443, end_date=20220126T033443
[2022-01-26 00:34:43,416] {standard_task_runner.py:89} ERROR - Failed to execute job 469 for task creating_table
Traceback (most recent call last):
  File "/home/uiliam/sandbox/lib/python3.9/site-packages/airflow/task/task_runner/standard_task_runner.py", line 85, in _start_by_fork
    args.func(args, dag=self.dag)
  File "/home/uiliam/sandbox/lib/python3.9/site-packages/airflow/cli/cli_parser.py", line 48, in command
    return func(*args, **kwargs)
  File "/home/uiliam/sandbox/lib/python3.9/site-packages/airflow/utils/cli.py", line 92, in wrapper
    return f(*args, **kwargs)
  File "/home/uiliam/sandbox/lib/python3.9/site-packages/airflow/cli/commands/task_command.py", line 298, in task_run
    _run_task_by_selected_method(args, dag, ti)
  File "/home/uiliam/sandbox/lib/python3.9/site-packages/airflow/cli/commands/task_command.py", line 107, in _run_task_by_selected_method
    _run_raw_task(args, ti)
  File "/home/uiliam/sandbox/lib/python3.9/site-packages/airflow/cli/commands/task_command.py", line 180, in _run_raw_task
    ti._run_raw_task(
  File "/home/uiliam/sandbox/lib/python3.9/site-packages/airflow/utils/session.py", line 70, in wrapper
    return func(*args, session=session, **kwargs)
  File "/home/uiliam/sandbox/lib/python3.9/site-packages/airflow/models/taskinstance.py", line 1329, in _run_raw_task
    self._execute_task_with_callbacks(context)
  File "/home/uiliam/sandbox/lib/python3.9/site-packages/airflow/models/taskinstance.py", line 1455, in _execute_task_with_callbacks
    result = self._execute_task(context, self.task)
  File "/home/uiliam/sandbox/lib/python3.9/site-packages/airflow/models/taskinstance.py", line 1511, in _execute_task
    result = execute_callable(context=context)
  File "/home/uiliam/sandbox/lib/python3.9/site-packages/airflow/providers/sqlite/operators/sqlite.py", line 63, in execute
    hook.run(self.sql, parameters=self.parameters)
  File "/home/uiliam/sandbox/lib/python3.9/site-packages/airflow/hooks/dbapi.py", line 198, in run
    with closing(self.get_conn()) as conn:
  File "/home/uiliam/sandbox/lib/python3.9/site-packages/airflow/providers/sqlite/hooks/sqlite.py", line 35, in get_conn
    airflow_conn = self.get_connection(conn_id)
  File "/home/uiliam/sandbox/lib/python3.9/site-packages/airflow/hooks/base.py", line 68, in get_connection
    conn = Connection.get_connection_from_secrets(conn_id)
  File "/home/uiliam/sandbox/lib/python3.9/site-packages/airflow/models/connection.py", line 410, in get_connection_from_secrets
    raise AirflowNotFoundException(f"The conn_id `{conn_id}` isn't defined")
airflow.exceptions.AirflowNotFoundException: The conn_id `db_sqlite` isn't defined
[2022-01-26 00:34:43,445] {local_task_job.py:154} INFO - Task exited with return code 1
[2022-01-26 00:34:43,495] {local_task_job.py:264} INFO - 0 downstream tasks scheduled from follow-on schedule check
[2022-01-26 01:45:17,831] {taskinstance.py:1032} INFO - Dependencies all met for <TaskInstance: user_processing.creating_table scheduled__2021-11-26T00:00:00+00:00 [queued]>
[2022-01-26 01:45:17,842] {taskinstance.py:1032} INFO - Dependencies all met for <TaskInstance: user_processing.creating_table scheduled__2021-11-26T00:00:00+00:00 [queued]>
[2022-01-26 01:45:17,842] {taskinstance.py:1238} INFO - 
--------------------------------------------------------------------------------
[2022-01-26 01:45:17,842] {taskinstance.py:1239} INFO - Starting attempt 1 of 1
[2022-01-26 01:45:17,842] {taskinstance.py:1240} INFO - 
--------------------------------------------------------------------------------
[2022-01-26 01:45:17,855] {taskinstance.py:1259} INFO - Executing <Task(SqliteOperator): creating_table> on 2021-11-26 00:00:00+00:00
[2022-01-26 01:45:17,860] {standard_task_runner.py:52} INFO - Started process 232963 to run task
[2022-01-26 01:45:17,864] {standard_task_runner.py:76} INFO - Running: ['airflow', 'tasks', 'run', 'user_processing', 'creating_table', 'scheduled__2021-11-26T00:00:00+00:00', '--job-id', '861', '--raw', '--subdir', 'DAGS_FOLDER/user_processing.py', '--cfg-path', '/tmp/tmphda6ordu', '--error-file', '/tmp/tmpddvk4jph']
[2022-01-26 01:45:17,865] {standard_task_runner.py:77} INFO - Job 861: Subtask creating_table
[2022-01-26 01:45:17,920] {logging_mixin.py:109} INFO - Running <TaskInstance: user_processing.creating_table scheduled__2021-11-26T00:00:00+00:00 [running]> on host uiliam-Vostro-15-3515
[2022-01-26 01:45:17,975] {taskinstance.py:1424} INFO - Exporting the following env vars:
AIRFLOW_CTX_DAG_OWNER=airflow
AIRFLOW_CTX_DAG_ID=user_processing
AIRFLOW_CTX_TASK_ID=creating_table
AIRFLOW_CTX_EXECUTION_DATE=2021-11-26T00:00:00+00:00
AIRFLOW_CTX_DAG_RUN_ID=scheduled__2021-11-26T00:00:00+00:00
[2022-01-26 01:45:17,976] {sqlite.py:61} INFO - Executing: 
            CREATE TABLE IF NOT EXISTS users (
            first_name TEXT NOT NULL,
            lastname TEXT NOT NULL,
            country TEXT NOT NULL,
            username TEXT NOT NULL,
            password TEXT NOT NULL,
            email TEXT NOT NULL PRIMARY KEY
            );
            
[2022-01-26 01:45:18,000] {taskinstance.py:1700} ERROR - Task failed with exception
Traceback (most recent call last):
  File "/home/uiliam/sandbox/lib/python3.9/site-packages/airflow/models/taskinstance.py", line 1329, in _run_raw_task
    self._execute_task_with_callbacks(context)
  File "/home/uiliam/sandbox/lib/python3.9/site-packages/airflow/models/taskinstance.py", line 1455, in _execute_task_with_callbacks
    result = self._execute_task(context, self.task)
  File "/home/uiliam/sandbox/lib/python3.9/site-packages/airflow/models/taskinstance.py", line 1511, in _execute_task
    result = execute_callable(context=context)
  File "/home/uiliam/sandbox/lib/python3.9/site-packages/airflow/providers/sqlite/operators/sqlite.py", line 63, in execute
    hook.run(self.sql, parameters=self.parameters)
  File "/home/uiliam/sandbox/lib/python3.9/site-packages/airflow/hooks/dbapi.py", line 198, in run
    with closing(self.get_conn()) as conn:
  File "/home/uiliam/sandbox/lib/python3.9/site-packages/airflow/providers/sqlite/hooks/sqlite.py", line 35, in get_conn
    airflow_conn = self.get_connection(conn_id)
  File "/home/uiliam/sandbox/lib/python3.9/site-packages/airflow/hooks/base.py", line 68, in get_connection
    conn = Connection.get_connection_from_secrets(conn_id)
  File "/home/uiliam/sandbox/lib/python3.9/site-packages/airflow/models/connection.py", line 410, in get_connection_from_secrets
    raise AirflowNotFoundException(f"The conn_id `{conn_id}` isn't defined")
airflow.exceptions.AirflowNotFoundException: The conn_id `db_sqlite` isn't defined
[2022-01-26 01:45:18,009] {taskinstance.py:1267} INFO - Marking task as FAILED. dag_id=user_processing, task_id=creating_table, execution_date=20211126T000000, start_date=20220126T044517, end_date=20220126T044518
[2022-01-26 01:45:18,019] {standard_task_runner.py:89} ERROR - Failed to execute job 861 for task creating_table
Traceback (most recent call last):
  File "/home/uiliam/sandbox/lib/python3.9/site-packages/airflow/task/task_runner/standard_task_runner.py", line 85, in _start_by_fork
    args.func(args, dag=self.dag)
  File "/home/uiliam/sandbox/lib/python3.9/site-packages/airflow/cli/cli_parser.py", line 48, in command
    return func(*args, **kwargs)
  File "/home/uiliam/sandbox/lib/python3.9/site-packages/airflow/utils/cli.py", line 92, in wrapper
    return f(*args, **kwargs)
  File "/home/uiliam/sandbox/lib/python3.9/site-packages/airflow/cli/commands/task_command.py", line 298, in task_run
    _run_task_by_selected_method(args, dag, ti)
  File "/home/uiliam/sandbox/lib/python3.9/site-packages/airflow/cli/commands/task_command.py", line 107, in _run_task_by_selected_method
    _run_raw_task(args, ti)
  File "/home/uiliam/sandbox/lib/python3.9/site-packages/airflow/cli/commands/task_command.py", line 180, in _run_raw_task
    ti._run_raw_task(
  File "/home/uiliam/sandbox/lib/python3.9/site-packages/airflow/utils/session.py", line 70, in wrapper
    return func(*args, session=session, **kwargs)
  File "/home/uiliam/sandbox/lib/python3.9/site-packages/airflow/models/taskinstance.py", line 1329, in _run_raw_task
    self._execute_task_with_callbacks(context)
  File "/home/uiliam/sandbox/lib/python3.9/site-packages/airflow/models/taskinstance.py", line 1455, in _execute_task_with_callbacks
    result = self._execute_task(context, self.task)
  File "/home/uiliam/sandbox/lib/python3.9/site-packages/airflow/models/taskinstance.py", line 1511, in _execute_task
    result = execute_callable(context=context)
  File "/home/uiliam/sandbox/lib/python3.9/site-packages/airflow/providers/sqlite/operators/sqlite.py", line 63, in execute
    hook.run(self.sql, parameters=self.parameters)
  File "/home/uiliam/sandbox/lib/python3.9/site-packages/airflow/hooks/dbapi.py", line 198, in run
    with closing(self.get_conn()) as conn:
  File "/home/uiliam/sandbox/lib/python3.9/site-packages/airflow/providers/sqlite/hooks/sqlite.py", line 35, in get_conn
    airflow_conn = self.get_connection(conn_id)
  File "/home/uiliam/sandbox/lib/python3.9/site-packages/airflow/hooks/base.py", line 68, in get_connection
    conn = Connection.get_connection_from_secrets(conn_id)
  File "/home/uiliam/sandbox/lib/python3.9/site-packages/airflow/models/connection.py", line 410, in get_connection_from_secrets
    raise AirflowNotFoundException(f"The conn_id `{conn_id}` isn't defined")
airflow.exceptions.AirflowNotFoundException: The conn_id `db_sqlite` isn't defined
[2022-01-26 01:45:18,035] {local_task_job.py:154} INFO - Task exited with return code 1
[2022-01-26 01:45:18,085] {local_task_job.py:264} INFO - 0 downstream tasks scheduled from follow-on schedule check
