[2022-01-26 00:35:50,368] {taskinstance.py:1032} INFO - Dependencies all met for <TaskInstance: user_processing.creating_table scheduled__2022-01-10T00:00:00+00:00 [queued]>
[2022-01-26 00:35:50,383] {taskinstance.py:1032} INFO - Dependencies all met for <TaskInstance: user_processing.creating_table scheduled__2022-01-10T00:00:00+00:00 [queued]>
[2022-01-26 00:35:50,383] {taskinstance.py:1238} INFO - 
--------------------------------------------------------------------------------
[2022-01-26 00:35:50,383] {taskinstance.py:1239} INFO - Starting attempt 1 of 1
[2022-01-26 00:35:50,384] {taskinstance.py:1240} INFO - 
--------------------------------------------------------------------------------
[2022-01-26 00:35:50,400] {taskinstance.py:1259} INFO - Executing <Task(SqliteOperator): creating_table> on 2022-01-10 00:00:00+00:00
[2022-01-26 00:35:50,406] {standard_task_runner.py:52} INFO - Started process 157828 to run task
[2022-01-26 00:35:50,410] {standard_task_runner.py:76} INFO - Running: ['airflow', 'tasks', 'run', 'user_processing', 'creating_table', 'scheduled__2022-01-10T00:00:00+00:00', '--job-id', '514', '--raw', '--subdir', 'DAGS_FOLDER/user_processing.py', '--cfg-path', '/tmp/tmpvmalvr8c', '--error-file', '/tmp/tmpn35wn9ae']
[2022-01-26 00:35:50,411] {standard_task_runner.py:77} INFO - Job 514: Subtask creating_table
[2022-01-26 00:35:50,477] {logging_mixin.py:109} INFO - Running <TaskInstance: user_processing.creating_table scheduled__2022-01-10T00:00:00+00:00 [running]> on host uiliam-Vostro-15-3515
[2022-01-26 00:35:50,547] {taskinstance.py:1424} INFO - Exporting the following env vars:
AIRFLOW_CTX_DAG_OWNER=airflow
AIRFLOW_CTX_DAG_ID=user_processing
AIRFLOW_CTX_TASK_ID=creating_table
AIRFLOW_CTX_EXECUTION_DATE=2022-01-10T00:00:00+00:00
AIRFLOW_CTX_DAG_RUN_ID=scheduled__2022-01-10T00:00:00+00:00
[2022-01-26 00:35:50,548] {sqlite.py:61} INFO - Executing: 
            CREATE TABLE IF NOT EXISTS users (
            first_name TEXT NOT NULL,
            lastname TEXT NOT NULL,
            country TEXT NOT NULL,
            username TEXT NOT NULL,
            password TEXT NOT NULL,
            email TEXT NOT NULL PRIMARY KEY
            );
            
[2022-01-26 00:35:50,576] {taskinstance.py:1700} ERROR - Task failed with exception
Traceback (most recent call last):
  File "/home/uiliam/sandbox/lib/python3.9/site-packages/airflow/models/taskinstance.py", line 1329, in _run_raw_task
    self._execute_task_with_callbacks(context)
  File "/home/uiliam/sandbox/lib/python3.9/site-packages/airflow/models/taskinstance.py", line 1455, in _execute_task_with_callbacks
    result = self._execute_task(context, self.task)
  File "/home/uiliam/sandbox/lib/python3.9/site-packages/airflow/models/taskinstance.py", line 1511, in _execute_task
    result = execute_callable(context=context)
  File "/home/uiliam/sandbox/lib/python3.9/site-packages/airflow/providers/sqlite/operators/sqlite.py", line 63, in execute
    hook.run(self.sql, parameters=self.parameters)
  File "/home/uiliam/sandbox/lib/python3.9/site-packages/airflow/hooks/dbapi.py", line 198, in run
    with closing(self.get_conn()) as conn:
  File "/home/uiliam/sandbox/lib/python3.9/site-packages/airflow/providers/sqlite/hooks/sqlite.py", line 35, in get_conn
    airflow_conn = self.get_connection(conn_id)
  File "/home/uiliam/sandbox/lib/python3.9/site-packages/airflow/hooks/base.py", line 68, in get_connection
    conn = Connection.get_connection_from_secrets(conn_id)
  File "/home/uiliam/sandbox/lib/python3.9/site-packages/airflow/models/connection.py", line 410, in get_connection_from_secrets
    raise AirflowNotFoundException(f"The conn_id `{conn_id}` isn't defined")
airflow.exceptions.AirflowNotFoundException: The conn_id `db_sqlite` isn't defined
[2022-01-26 00:35:50,588] {taskinstance.py:1267} INFO - Marking task as FAILED. dag_id=user_processing, task_id=creating_table, execution_date=20220110T000000, start_date=20220126T033550, end_date=20220126T033550
[2022-01-26 00:35:50,603] {standard_task_runner.py:89} ERROR - Failed to execute job 514 for task creating_table
Traceback (most recent call last):
  File "/home/uiliam/sandbox/lib/python3.9/site-packages/airflow/task/task_runner/standard_task_runner.py", line 85, in _start_by_fork
    args.func(args, dag=self.dag)
  File "/home/uiliam/sandbox/lib/python3.9/site-packages/airflow/cli/cli_parser.py", line 48, in command
    return func(*args, **kwargs)
  File "/home/uiliam/sandbox/lib/python3.9/site-packages/airflow/utils/cli.py", line 92, in wrapper
    return f(*args, **kwargs)
  File "/home/uiliam/sandbox/lib/python3.9/site-packages/airflow/cli/commands/task_command.py", line 298, in task_run
    _run_task_by_selected_method(args, dag, ti)
  File "/home/uiliam/sandbox/lib/python3.9/site-packages/airflow/cli/commands/task_command.py", line 107, in _run_task_by_selected_method
    _run_raw_task(args, ti)
  File "/home/uiliam/sandbox/lib/python3.9/site-packages/airflow/cli/commands/task_command.py", line 180, in _run_raw_task
    ti._run_raw_task(
  File "/home/uiliam/sandbox/lib/python3.9/site-packages/airflow/utils/session.py", line 70, in wrapper
    return func(*args, session=session, **kwargs)
  File "/home/uiliam/sandbox/lib/python3.9/site-packages/airflow/models/taskinstance.py", line 1329, in _run_raw_task
    self._execute_task_with_callbacks(context)
  File "/home/uiliam/sandbox/lib/python3.9/site-packages/airflow/models/taskinstance.py", line 1455, in _execute_task_with_callbacks
    result = self._execute_task(context, self.task)
  File "/home/uiliam/sandbox/lib/python3.9/site-packages/airflow/models/taskinstance.py", line 1511, in _execute_task
    result = execute_callable(context=context)
  File "/home/uiliam/sandbox/lib/python3.9/site-packages/airflow/providers/sqlite/operators/sqlite.py", line 63, in execute
    hook.run(self.sql, parameters=self.parameters)
  File "/home/uiliam/sandbox/lib/python3.9/site-packages/airflow/hooks/dbapi.py", line 198, in run
    with closing(self.get_conn()) as conn:
  File "/home/uiliam/sandbox/lib/python3.9/site-packages/airflow/providers/sqlite/hooks/sqlite.py", line 35, in get_conn
    airflow_conn = self.get_connection(conn_id)
  File "/home/uiliam/sandbox/lib/python3.9/site-packages/airflow/hooks/base.py", line 68, in get_connection
    conn = Connection.get_connection_from_secrets(conn_id)
  File "/home/uiliam/sandbox/lib/python3.9/site-packages/airflow/models/connection.py", line 410, in get_connection_from_secrets
    raise AirflowNotFoundException(f"The conn_id `{conn_id}` isn't defined")
airflow.exceptions.AirflowNotFoundException: The conn_id `db_sqlite` isn't defined
[2022-01-26 00:35:50,622] {local_task_job.py:154} INFO - Task exited with return code 1
[2022-01-26 00:35:50,669] {local_task_job.py:264} INFO - 0 downstream tasks scheduled from follow-on schedule check
[2022-01-26 01:46:10,385] {taskinstance.py:1032} INFO - Dependencies all met for <TaskInstance: user_processing.creating_table scheduled__2022-01-10T00:00:00+00:00 [queued]>
[2022-01-26 01:46:10,403] {taskinstance.py:1032} INFO - Dependencies all met for <TaskInstance: user_processing.creating_table scheduled__2022-01-10T00:00:00+00:00 [queued]>
[2022-01-26 01:46:10,404] {taskinstance.py:1238} INFO - 
--------------------------------------------------------------------------------
[2022-01-26 01:46:10,404] {taskinstance.py:1239} INFO - Starting attempt 1 of 1
[2022-01-26 01:46:10,404] {taskinstance.py:1240} INFO - 
--------------------------------------------------------------------------------
[2022-01-26 01:46:10,429] {taskinstance.py:1259} INFO - Executing <Task(SqliteOperator): creating_table> on 2022-01-10 00:00:00+00:00
[2022-01-26 01:46:10,438] {standard_task_runner.py:52} INFO - Started process 237123 to run task
[2022-01-26 01:46:10,443] {standard_task_runner.py:76} INFO - Running: ['airflow', 'tasks', 'run', 'user_processing', 'creating_table', 'scheduled__2022-01-10T00:00:00+00:00', '--job-id', '906', '--raw', '--subdir', 'DAGS_FOLDER/user_processing.py', '--cfg-path', '/tmp/tmpwgc7w9qp', '--error-file', '/tmp/tmp2evlsvps']
[2022-01-26 01:46:10,444] {standard_task_runner.py:77} INFO - Job 906: Subtask creating_table
[2022-01-26 01:46:10,541] {logging_mixin.py:109} INFO - Running <TaskInstance: user_processing.creating_table scheduled__2022-01-10T00:00:00+00:00 [running]> on host uiliam-Vostro-15-3515
[2022-01-26 01:46:10,622] {taskinstance.py:1424} INFO - Exporting the following env vars:
AIRFLOW_CTX_DAG_OWNER=airflow
AIRFLOW_CTX_DAG_ID=user_processing
AIRFLOW_CTX_TASK_ID=creating_table
AIRFLOW_CTX_EXECUTION_DATE=2022-01-10T00:00:00+00:00
AIRFLOW_CTX_DAG_RUN_ID=scheduled__2022-01-10T00:00:00+00:00
[2022-01-26 01:46:10,623] {sqlite.py:61} INFO - Executing: 
            CREATE TABLE IF NOT EXISTS users (
            first_name TEXT NOT NULL,
            lastname TEXT NOT NULL,
            country TEXT NOT NULL,
            username TEXT NOT NULL,
            password TEXT NOT NULL,
            email TEXT NOT NULL PRIMARY KEY
            );
            
[2022-01-26 01:46:10,801] {taskinstance.py:1700} ERROR - Task failed with exception
Traceback (most recent call last):
  File "/home/uiliam/sandbox/lib/python3.9/site-packages/airflow/models/taskinstance.py", line 1329, in _run_raw_task
    self._execute_task_with_callbacks(context)
  File "/home/uiliam/sandbox/lib/python3.9/site-packages/airflow/models/taskinstance.py", line 1455, in _execute_task_with_callbacks
    result = self._execute_task(context, self.task)
  File "/home/uiliam/sandbox/lib/python3.9/site-packages/airflow/models/taskinstance.py", line 1511, in _execute_task
    result = execute_callable(context=context)
  File "/home/uiliam/sandbox/lib/python3.9/site-packages/airflow/providers/sqlite/operators/sqlite.py", line 63, in execute
    hook.run(self.sql, parameters=self.parameters)
  File "/home/uiliam/sandbox/lib/python3.9/site-packages/airflow/hooks/dbapi.py", line 198, in run
    with closing(self.get_conn()) as conn:
  File "/home/uiliam/sandbox/lib/python3.9/site-packages/airflow/providers/sqlite/hooks/sqlite.py", line 35, in get_conn
    airflow_conn = self.get_connection(conn_id)
  File "/home/uiliam/sandbox/lib/python3.9/site-packages/airflow/hooks/base.py", line 68, in get_connection
    conn = Connection.get_connection_from_secrets(conn_id)
  File "/home/uiliam/sandbox/lib/python3.9/site-packages/airflow/models/connection.py", line 410, in get_connection_from_secrets
    raise AirflowNotFoundException(f"The conn_id `{conn_id}` isn't defined")
airflow.exceptions.AirflowNotFoundException: The conn_id `db_sqlite` isn't defined
[2022-01-26 01:46:10,815] {taskinstance.py:1267} INFO - Marking task as FAILED. dag_id=user_processing, task_id=creating_table, execution_date=20220110T000000, start_date=20220126T044610, end_date=20220126T044610
[2022-01-26 01:46:10,838] {standard_task_runner.py:89} ERROR - Failed to execute job 906 for task creating_table
Traceback (most recent call last):
  File "/home/uiliam/sandbox/lib/python3.9/site-packages/airflow/task/task_runner/standard_task_runner.py", line 85, in _start_by_fork
    args.func(args, dag=self.dag)
  File "/home/uiliam/sandbox/lib/python3.9/site-packages/airflow/cli/cli_parser.py", line 48, in command
    return func(*args, **kwargs)
  File "/home/uiliam/sandbox/lib/python3.9/site-packages/airflow/utils/cli.py", line 92, in wrapper
    return f(*args, **kwargs)
  File "/home/uiliam/sandbox/lib/python3.9/site-packages/airflow/cli/commands/task_command.py", line 298, in task_run
    _run_task_by_selected_method(args, dag, ti)
  File "/home/uiliam/sandbox/lib/python3.9/site-packages/airflow/cli/commands/task_command.py", line 107, in _run_task_by_selected_method
    _run_raw_task(args, ti)
  File "/home/uiliam/sandbox/lib/python3.9/site-packages/airflow/cli/commands/task_command.py", line 180, in _run_raw_task
    ti._run_raw_task(
  File "/home/uiliam/sandbox/lib/python3.9/site-packages/airflow/utils/session.py", line 70, in wrapper
    return func(*args, session=session, **kwargs)
  File "/home/uiliam/sandbox/lib/python3.9/site-packages/airflow/models/taskinstance.py", line 1329, in _run_raw_task
    self._execute_task_with_callbacks(context)
  File "/home/uiliam/sandbox/lib/python3.9/site-packages/airflow/models/taskinstance.py", line 1455, in _execute_task_with_callbacks
    result = self._execute_task(context, self.task)
  File "/home/uiliam/sandbox/lib/python3.9/site-packages/airflow/models/taskinstance.py", line 1511, in _execute_task
    result = execute_callable(context=context)
  File "/home/uiliam/sandbox/lib/python3.9/site-packages/airflow/providers/sqlite/operators/sqlite.py", line 63, in execute
    hook.run(self.sql, parameters=self.parameters)
  File "/home/uiliam/sandbox/lib/python3.9/site-packages/airflow/hooks/dbapi.py", line 198, in run
    with closing(self.get_conn()) as conn:
  File "/home/uiliam/sandbox/lib/python3.9/site-packages/airflow/providers/sqlite/hooks/sqlite.py", line 35, in get_conn
    airflow_conn = self.get_connection(conn_id)
  File "/home/uiliam/sandbox/lib/python3.9/site-packages/airflow/hooks/base.py", line 68, in get_connection
    conn = Connection.get_connection_from_secrets(conn_id)
  File "/home/uiliam/sandbox/lib/python3.9/site-packages/airflow/models/connection.py", line 410, in get_connection_from_secrets
    raise AirflowNotFoundException(f"The conn_id `{conn_id}` isn't defined")
airflow.exceptions.AirflowNotFoundException: The conn_id `db_sqlite` isn't defined
[2022-01-26 01:46:10,855] {local_task_job.py:154} INFO - Task exited with return code 1
[2022-01-26 01:46:10,919] {local_task_job.py:264} INFO - 0 downstream tasks scheduled from follow-on schedule check
